[2021-09-27 14:44:04,292] {taskinstance.py:903} INFO - Dependencies all met for <TaskInstance: my_dag.say_hello 2021-09-27T14:30:00+00:00 [queued]>
[2021-09-27 14:44:04,321] {taskinstance.py:903} INFO - Dependencies all met for <TaskInstance: my_dag.say_hello 2021-09-27T14:30:00+00:00 [queued]>
[2021-09-27 14:44:04,323] {taskinstance.py:1095} INFO - 
--------------------------------------------------------------------------------
[2021-09-27 14:44:04,323] {taskinstance.py:1096} INFO - Starting attempt 1 of 1
[2021-09-27 14:44:04,324] {taskinstance.py:1097} INFO - 
--------------------------------------------------------------------------------
[2021-09-27 14:44:04,334] {taskinstance.py:1115} INFO - Executing <Task(PythonOperator): say_hello> on 2021-09-27T14:30:00+00:00
[2021-09-27 14:44:04,338] {standard_task_runner.py:52} INFO - Started process 11606 to run task
[2021-09-27 14:44:04,344] {standard_task_runner.py:76} INFO - Running: ['***', 'tasks', 'run', 'my_dag', 'say_hello', '2021-09-27T14:30:00+00:00', '--job-id', '61', '--pool', 'default_pool', '--raw', '--subdir', 'DAGS_FOLDER/my_dag.py', '--cfg-path', '/tmp/tmpr0sz8o3d', '--error-file', '/tmp/tmpt8sw4daz']
[2021-09-27 14:44:04,352] {standard_task_runner.py:77} INFO - Job 61: Subtask say_hello
[2021-09-27 14:44:04,421] {logging_mixin.py:109} INFO - Running <TaskInstance: my_dag.say_hello 2021-09-27T14:30:00+00:00 [running]> on host 7c1d2d2abdb5
[2021-09-27 14:44:04,497] {taskinstance.py:1254} INFO - Exporting the following env vars:
AIRFLOW_CTX_DAG_OWNER=Veerawat
AIRFLOW_CTX_DAG_ID=my_dag
AIRFLOW_CTX_TASK_ID=say_hello
AIRFLOW_CTX_EXECUTION_DATE=2021-09-27T14:30:00+00:00
AIRFLOW_CTX_DAG_RUN_ID=scheduled__2021-09-27T14:30:00+00:00
[2021-09-27 14:44:04,500] {taskinstance.py:1463} ERROR - Task failed with exception
Traceback (most recent call last):
  File "/home/airflow/.local/lib/python3.6/site-packages/airflow/models/taskinstance.py", line 1165, in _run_raw_task
    self._prepare_and_execute_task_with_callbacks(context, task)
  File "/home/airflow/.local/lib/python3.6/site-packages/airflow/models/taskinstance.py", line 1283, in _prepare_and_execute_task_with_callbacks
    result = self._execute_task(context, task_copy)
  File "/home/airflow/.local/lib/python3.6/site-packages/airflow/models/taskinstance.py", line 1313, in _execute_task
    result = task_copy.execute(context=context)
  File "/home/airflow/.local/lib/python3.6/site-packages/airflow/operators/python.py", line 150, in execute
    return_value = self.execute_callable()
  File "/home/airflow/.local/lib/python3.6/site-packages/airflow/operators/python.py", line 161, in execute_callable
    return self.python_callable(*self.op_args, **self.op_kwargs)
  File "/opt/airflow/dags/my_dag.py", line 11, in _say_hello
    logging,info("Hello, SAKSIAM")
NameError: name 'info' is not defined
[2021-09-27 14:44:04,504] {taskinstance.py:1513} INFO - Marking task as FAILED. dag_id=my_dag, task_id=say_hello, execution_date=20210927T143000, start_date=20210927T144404, end_date=20210927T144404
[2021-09-27 14:44:04,559] {local_task_job.py:151} INFO - Task exited with return code 1
[2021-09-27 14:44:04,608] {local_task_job.py:261} INFO - 0 downstream tasks scheduled from follow-on schedule check
